<?xml version="1.0" encoding="utf-8"?>
<!-- This URDF was automatically created by SolidWorks to URDF Exporter! Originally created by Stephen Brawner (brawner@gmail.com) 
     Commit Version: 1.5.1-0-g916b5db  Build Version: 1.5.7152.31018
     For more information, please see http://wiki.ros.org/sw_urdf_exporter -->
<robot
  name="walker_description">
  <link
    name="base_link">
    <inertial>
      <origin
        xyz="0.26321 1.2785E-06 0.15671"
        rpy="0 0 0" />
      <mass
        value="3.5774" />
      <inertia
        ixx="0.29508"
        ixy="1.3791E-07"
        ixz="0.001404"
        iyy="0.26107"
        iyz="-2.7608E-07"
        izz="0.1867" />
    </inertial>
    <visual>
      <origin
        xyz="0 0 0"
        rpy="0 0 0" />
      <geometry>
        <mesh
          filename="package://walker_description/meshes/base_link.STL" />
      </geometry>
      <material
        name="">
        <color
          rgba="0.79216 0.81961 0.93333 1" />
      </material>
    </visual>
    <collision>
      <origin
        xyz="0 0 0"
        rpy="0 0 0" />
      <geometry>
        <mesh
          filename="package://walker_description/meshes/base_link.STL" />
      </geometry>
    </collision>
  </link>
  <link
    name="rear_right_wheel_link">
    <inertial>
      <origin
        xyz="0 0 0"
        rpy="0 0 0" />
      <mass
        value="0.18877" />
      <inertia
        ixx="0.00013887"
        ixy="-1.6386E-36"
        ixz="2.1452E-37"
        iyy="0.00013887"
        iyz="-7.5427E-20"
        izz="0.00026251" />
    </inertial>
    <visual>
      <origin
        xyz="0 0 0"
        rpy="0 0 0" />
      <geometry>
        <mesh
          filename="package://walker_description/meshes/rear_right_wheel_link.STL" />
      </geometry>
      <material
        name="">
        <color
          rgba="0.1 0.1 0.1 1" />
      </material>
    </visual>
    <collision>
      <origin
        xyz="0 0 0"
        rpy="0 0 0" />
      <geometry>
        <mesh
          filename="package://walker_description/meshes/rear_right_wheel_link.STL" />
      </geometry>
    </collision>
  </link>
  <joint
    name="rear_right_wheel_joint"
    type="continuous">
    <origin
      xyz="0 -0.301 -0.03"
      rpy="-1.5708 0 0" />
    <parent
      link="base_link" />
    <child
      link="rear_right_wheel_link" />
    <axis
      xyz="0 0.099176 -0.99507" />
    <dynamics
      friction="0.001" />
  </joint>
  <link
    name="rear_left_wheel_link">
    <inertial>
      <origin
        xyz="0 6.9389E-18 0"
        rpy="0 0 0" />
      <mass
        value="0.18877" />
      <inertia
        ixx="0.00013887"
        ixy="4.2884E-36"
        ixz="-8.5028E-20"
        iyy="0.00013887"
        iyz="-7.5708E-21"
        izz="0.00026251" />
    </inertial>
    <visual>
      <origin
        xyz="0 0 0"
        rpy="0 0 0" />
      <geometry>
        <mesh
          filename="package://walker_description/meshes/rear_left_wheel_link.STL" />
      </geometry>
      <material
        name="">
        <color
          rgba="0.1 0.1 0.1 1" />
      </material>
    </visual>
    <collision>
      <origin
        xyz="0 0 0"
        rpy="0 0 0" />
      <geometry>
        <mesh
          filename="package://walker_description/meshes/rear_left_wheel_link.STL" />
      </geometry>
    </collision>
  </link>
  <joint
    name="rear_left_wheel_joint"
    type="continuous">
    <origin
      xyz="0 0.301 -0.03"
      rpy="-1.5708 0 0" />
    <parent
      link="base_link" />
    <child
      link="rear_left_wheel_link" />
    <axis
      xyz="0 0.099176 0.99507" />
    <limit
      lower="0"
      upper="0"
      effort="0"
      velocity="0" />
    <dynamics
      friction="0.001" />
  </joint>
  <link
    name="force_sensor_link">
    <inertial>
      <origin
        xyz="0.0041884 0.0015924 0.015541"
        rpy="0 0 0" />
      <mass
        value="0.17912" />
      <inertia
        ixx="8.7156E-05"
        ixy="-9.4168E-06"
        ixz="4.2663E-06"
        iyy="0.00011084"
        iyz="1.6414E-06"
        izz="0.0001673" />
    </inertial>
    <visual>
      <origin
        xyz="0 0 0"
        rpy="0 0 0" />
      <geometry>
        <mesh
          filename="package://walker_description/meshes/force_sensor_link.STL" />
      </geometry>
      <material
        name="">
        <color
          rgba="0.9569 0.2196 0 1" />
      </material>
    </visual>
    <collision>
      <origin
        xyz="0 0 0"
        rpy="0 0 0" />
      <geometry>
        <mesh
          filename="package://walker_description/meshes/force_sensor_link.STL" />
      </geometry>
    </collision>
  </link>
  <joint
    name="force_sensor_joint"
    type="fixed">
    <origin
      xyz="0.16109 0 0.81585"
      rpy="0 0 -1.5708" />
    <parent
      link="base_link" />
    <child
      link="force_sensor_link" />
    <axis
      xyz="0 0 0" />
  </joint>
  <link
    name="handrail_link">
    <inertial>
      <origin
        xyz="-0.083491 1.4788E-17 -2.9354E-05"
        rpy="0 0 0" />
      <mass
        value="1.6842" />
      <inertia
        ixx="0.048123"
        ixy="-3.5053E-19"
        ixz="4.1278E-06"
        iyy="0.012317"
        iyz="-1.8415E-19"
        izz="0.06002" />
    </inertial>
    <visual>
      <origin
        xyz="0 0 0"
        rpy="0 0 0" />
      <geometry>
        <mesh
          filename="package://walker_description/meshes/handrail_link.STL" />
      </geometry>
      <material
        name="">
        <color
          rgba="0.79216 0.81961 0.93333 1" />
      </material>
    </visual>
    <collision>
      <origin
        xyz="0 0 0"
        rpy="0 0 0" />
      <geometry>
        <mesh
          filename="package://walker_description/meshes/handrail_link.STL" />
      </geometry>
    </collision>
  </link>
  <joint
    name="handrail_joint"
    type="fixed">
    <origin
      xyz="0 0 0.0565"
      rpy="0 0 1.5708" />
    <parent
      link="force_sensor_link" />
    <child
      link="handrail_link" />
    <axis
      xyz="0 0 0" />
  </joint>
  <link
    name="front_right_caster_wheel_link">
    <inertial>
      <origin
        xyz="-0.0042994 2.0823E-06 -0.0092241"
        rpy="0 0 0" />
      <mass
        value="0.062864" />
      <inertia
        ixx="1.8333E-05"
        ixy="-2.766E-10"
        ixz="-4.2964E-07"
        iyy="3.1598E-05"
        iyz="-9.745E-11"
        izz="2.0211E-05" />
    </inertial>
    <visual>
      <origin
        xyz="0 0 0"
        rpy="0 0 0" />
      <geometry>
        <mesh
          filename="package://walker_description/meshes/front_right_caster_wheel_link.STL" />
      </geometry>
      <material
        name="">
        <color
          rgba="0.75294 0.75294 0.75294 1" />
      </material>
    </visual>
    <collision>
      <origin
        xyz="0 0 0"
        rpy="0 0 0" />
      <geometry>
        <mesh
          filename="package://walker_description/meshes/front_right_caster_wheel_link.STL" />
      </geometry>
    </collision>
  </link>
  <joint
    name="front_right_caster_wheel_joint"
    type="fixed">
    <origin
      xyz="0.39293 -0.17843 -0.037217"
      rpy="0 0 0" />
    <parent
      link="base_link" />
    <child
      link="front_right_caster_wheel_link" />
    <axis
      xyz="0 0 0" />
  </joint>
  <link
    name="front_left_caster_wheel_link">
    <inertial>
      <origin
        xyz="-0.0042994 2.0823E-06 -0.0092241"
        rpy="0 0 0" />
      <mass
        value="0.062864" />
      <inertia
        ixx="1.8333E-05"
        ixy="-2.766E-10"
        ixz="-4.2964E-07"
        iyy="3.1598E-05"
        iyz="-9.745E-11"
        izz="2.0211E-05" />
    </inertial>
    <visual>
      <origin
        xyz="0 0 0"
        rpy="0 0 0" />
      <geometry>
        <mesh
          filename="package://walker_description/meshes/front_left_caster_wheel_link.STL" />
      </geometry>
      <material
        name="">
        <color
          rgba="0.75294 0.75294 0.75294 1" />
      </material>
    </visual>
    <collision>
      <origin
        xyz="0 0 0"
        rpy="0 0 0" />
      <geometry>
        <mesh
          filename="package://walker_description/meshes/front_left_caster_wheel_link.STL" />
      </geometry>
    </collision>
  </link>
  <joint
    name="front_left_caster_wheel_joint"
    type="fixed">
    <origin
      xyz="0.39293 0.17843 -0.037217"
      rpy="0 0 0" />
    <parent
      link="base_link" />
    <child
      link="front_left_caster_wheel_link" />
    <axis
      xyz="0 0 0" />
  </joint>
</robot>